{
 "cells": [
  {
   "cell_type": "code",
   "execution_count": 1,
   "metadata": {},
   "outputs": [],
   "source": [
    "import os"
   ]
  },
  {
   "cell_type": "code",
   "execution_count": 2,
   "metadata": {},
   "outputs": [
    {
     "data": {
      "text/plain": [
       "'/Users/cyber/MLProjectWineQuality/research'"
      ]
     },
     "execution_count": 2,
     "metadata": {},
     "output_type": "execute_result"
    }
   ],
   "source": [
    "%pwd"
   ]
  },
  {
   "cell_type": "code",
   "execution_count": 3,
   "metadata": {},
   "outputs": [],
   "source": [
    "os.chdir(\"../\")"
   ]
  },
  {
   "cell_type": "code",
   "execution_count": 4,
   "metadata": {},
   "outputs": [
    {
     "data": {
      "text/plain": [
       "'/Users/cyber/MLProjectWineQuality'"
      ]
     },
     "execution_count": 4,
     "metadata": {},
     "output_type": "execute_result"
    }
   ],
   "source": [
    "%pwd"
   ]
  },
  {
   "cell_type": "code",
   "execution_count": 5,
   "metadata": {},
   "outputs": [],
   "source": [
    "from dataclasses import dataclass\n",
    "from pathlib import Path\n",
    "\n",
    "\n",
    "@dataclass(frozen=True)\n",
    "class DataTransformationConfig:\n",
    "    root_dir: Path\n",
    "    data_path: Path"
   ]
  },
  {
   "cell_type": "code",
   "execution_count": 6,
   "metadata": {},
   "outputs": [],
   "source": [
    "from MLProject.constants import *\n",
    "from MLProject.utils.common import read_yml, create_directories"
   ]
  },
  {
   "cell_type": "code",
   "execution_count": 17,
   "metadata": {},
   "outputs": [],
   "source": [
    "class ConfigurationManager:\n",
    "    \n",
    "    def __init__(\n",
    "        self,\n",
    "        config_filepath = CONFIG_FILE_PATH,\n",
    "        params_filepath = PARAMS_FILE_PATH,\n",
    "        schema_filepath = SCHEMA_FILE_PATH):\n",
    "        \n",
    "        self.config = read_yml(config_filepath)\n",
    "        self.params = read_yml(params_filepath)\n",
    "        self.schema = read_yml(schema_filepath)\n",
    "        \n",
    "        create_directories([self.config.artifacts_root])\n",
    "        \n",
    "        \n",
    "    \n",
    "    def get_data_transformation_config(self) -> DataTransformationConfig:\n",
    "        config = self.config.data_transformation\n",
    "        \n",
    "        create_directories([config.root_dir])\n",
    "        \n",
    "        data_transformation_config = DataTransformationConfig(\n",
    "            root_dir=config.root_dir,\n",
    "            data_path=config.data_path,\n",
    "        )\n",
    "        \n",
    "        return data_transformation_config"
   ]
  },
  {
   "cell_type": "code",
   "execution_count": 18,
   "metadata": {},
   "outputs": [],
   "source": [
    "import os\n",
    "from MLProject import logger\n",
    "from sklearn.model_selection import train_test_split\n",
    "import pandas as pd"
   ]
  },
  {
   "cell_type": "code",
   "execution_count": 19,
   "metadata": {},
   "outputs": [],
   "source": [
    "class DataTransformation:\n",
    "    \n",
    "    def __init__(self, config: DataTransformationConfig):\n",
    "        self.config = config\n",
    "        \n",
    "    ## Note: You can add different data transformation techniques such as Scaler, PCA and all\n",
    "    #You can perform all kinds of EDA in ML cycle here before passing this data to the model\n",
    "    \n",
    "    # I am only adding train_test_split cz this data is already cleaned up\n",
    "    \n",
    "    def train_test_splitting(self):\n",
    "        data = pd.read_csv(self.config.data_path)\n",
    "        \n",
    "        # Split the data into training and test sets. (0.75, 0.25) split\n",
    "        train, test = train_test_split(data)\n",
    "        \n",
    "        train.to_csv(os.path.join(self.config.root_dir, \"train csv\"),index = False)\n",
    "        test.to_csv(os.path.join(self.config.root_dir, \"test csv\"),index = False)\n",
    "        \n",
    "        logger.info(\"Splitted data into training and test sets\")\n",
    "        logger.info(train.shape)\n",
    "        logger.info(test.shape)\n",
    "        \n",
    "        print(train.shape)\n",
    "        print(test.shape)        "
   ]
  },
  {
   "cell_type": "code",
   "execution_count": 20,
   "metadata": {},
   "outputs": [
    {
     "name": "stdout",
     "output_type": "stream",
     "text": [
      "[2025-02-04 10:50:35,334: INFO: common: yml_file: config/config.yml loaded successfully]\n",
      "[2025-02-04 10:50:35,401: INFO: common: yml_file: params.yml loaded successfully]\n",
      "[2025-02-04 10:50:35,409: INFO: common: yml_file: schema.yml loaded successfully]\n",
      "[2025-02-04 10:50:35,411: INFO: common: created directory at: artifacts]\n",
      "[2025-02-04 10:50:35,422: INFO: common: created directory at: artifacts/data_validation]\n"
     ]
    },
    {
     "ename": "BoxKeyError",
     "evalue": "\"'ConfigBox' object has no attribute 'data_path'\"",
     "output_type": "error",
     "traceback": [
      "\u001b[0;31m---------------------------------------------------------------------------\u001b[0m",
      "\u001b[0;31mKeyError\u001b[0m                                  Traceback (most recent call last)",
      "File \u001b[0;32m/opt/anaconda3/envs/mlproj/lib/python3.8/site-packages/box/box.py:503\u001b[0m, in \u001b[0;36mbox.box.Box.__getitem__\u001b[0;34m()\u001b[0m\n",
      "\u001b[0;31mKeyError\u001b[0m: 'data_path'",
      "\nThe above exception was the direct cause of the following exception:\n",
      "\u001b[0;31mBoxKeyError\u001b[0m                               Traceback (most recent call last)",
      "File \u001b[0;32m/opt/anaconda3/envs/mlproj/lib/python3.8/site-packages/box/box.py:536\u001b[0m, in \u001b[0;36mbox.box.Box.__getattr__\u001b[0;34m()\u001b[0m\n",
      "File \u001b[0;32m/opt/anaconda3/envs/mlproj/lib/python3.8/site-packages/box/box.py:524\u001b[0m, in \u001b[0;36mbox.box.Box.__getitem__\u001b[0;34m()\u001b[0m\n",
      "\u001b[0;31mBoxKeyError\u001b[0m: \"'data_path'\"",
      "\nDuring handling of the above exception, another exception occurred:\n",
      "\u001b[0;31mAttributeError\u001b[0m                            Traceback (most recent call last)",
      "File \u001b[0;32m/opt/anaconda3/envs/mlproj/lib/python3.8/site-packages/box/box.py:538\u001b[0m, in \u001b[0;36mbox.box.Box.__getattr__\u001b[0;34m()\u001b[0m\n",
      "\u001b[0;31mAttributeError\u001b[0m: 'ConfigBox' object has no attribute 'data_path'",
      "\nThe above exception was the direct cause of the following exception:\n",
      "\u001b[0;31mBoxKeyError\u001b[0m                               Traceback (most recent call last)",
      "File \u001b[0;32m/opt/anaconda3/envs/mlproj/lib/python3.8/site-packages/box/config_box.py:28\u001b[0m, in \u001b[0;36mbox.config_box.ConfigBox.__getattr__\u001b[0;34m()\u001b[0m\n",
      "File \u001b[0;32m/opt/anaconda3/envs/mlproj/lib/python3.8/site-packages/box/box.py:552\u001b[0m, in \u001b[0;36mbox.box.Box.__getattr__\u001b[0;34m()\u001b[0m\n",
      "\u001b[0;31mBoxKeyError\u001b[0m: \"'ConfigBox' object has no attribute 'data_path'\"",
      "\nDuring handling of the above exception, another exception occurred:\n",
      "\u001b[0;31mKeyError\u001b[0m                                  Traceback (most recent call last)",
      "File \u001b[0;32m/opt/anaconda3/envs/mlproj/lib/python3.8/site-packages/box/box.py:503\u001b[0m, in \u001b[0;36mbox.box.Box.__getitem__\u001b[0;34m()\u001b[0m\n",
      "\u001b[0;31mKeyError\u001b[0m: 'data_path'",
      "\nThe above exception was the direct cause of the following exception:\n",
      "\u001b[0;31mBoxKeyError\u001b[0m                               Traceback (most recent call last)",
      "File \u001b[0;32m/opt/anaconda3/envs/mlproj/lib/python3.8/site-packages/box/box.py:536\u001b[0m, in \u001b[0;36mbox.box.Box.__getattr__\u001b[0;34m()\u001b[0m\n",
      "File \u001b[0;32m/opt/anaconda3/envs/mlproj/lib/python3.8/site-packages/box/box.py:524\u001b[0m, in \u001b[0;36mbox.box.Box.__getitem__\u001b[0;34m()\u001b[0m\n",
      "\u001b[0;31mBoxKeyError\u001b[0m: \"'data_path'\"",
      "\nDuring handling of the above exception, another exception occurred:\n",
      "\u001b[0;31mAttributeError\u001b[0m                            Traceback (most recent call last)",
      "File \u001b[0;32m/opt/anaconda3/envs/mlproj/lib/python3.8/site-packages/box/box.py:538\u001b[0m, in \u001b[0;36mbox.box.Box.__getattr__\u001b[0;34m()\u001b[0m\n",
      "\u001b[0;31mAttributeError\u001b[0m: 'ConfigBox' object has no attribute 'data_path'",
      "\nThe above exception was the direct cause of the following exception:\n",
      "\u001b[0;31mBoxKeyError\u001b[0m                               Traceback (most recent call last)",
      "Cell \u001b[0;32mIn[20], line 7\u001b[0m\n\u001b[1;32m      5\u001b[0m     data_transformation\u001b[38;5;241m.\u001b[39mtrain_test_splitting()\n\u001b[1;32m      6\u001b[0m \u001b[38;5;28;01mexcept\u001b[39;00m \u001b[38;5;167;01mException\u001b[39;00m \u001b[38;5;28;01mas\u001b[39;00m e:\n\u001b[0;32m----> 7\u001b[0m     \u001b[38;5;28;01mraise\u001b[39;00m e\n",
      "Cell \u001b[0;32mIn[20], line 3\u001b[0m\n\u001b[1;32m      1\u001b[0m \u001b[38;5;28;01mtry\u001b[39;00m:\n\u001b[1;32m      2\u001b[0m     config \u001b[38;5;241m=\u001b[39m ConfigurationManager()\n\u001b[0;32m----> 3\u001b[0m     data_transformation_config \u001b[38;5;241m=\u001b[39m \u001b[43mconfig\u001b[49m\u001b[38;5;241;43m.\u001b[39;49m\u001b[43mget_data_transformation_config\u001b[49m\u001b[43m(\u001b[49m\u001b[43m)\u001b[49m\n\u001b[1;32m      4\u001b[0m     data_transformation \u001b[38;5;241m=\u001b[39m DataTransformation(config\u001b[38;5;241m=\u001b[39mdata_transformation_config)\n\u001b[1;32m      5\u001b[0m     data_transformation\u001b[38;5;241m.\u001b[39mtrain_test_splitting()\n",
      "Cell \u001b[0;32mIn[17], line 24\u001b[0m, in \u001b[0;36mConfigurationManager.get_data_transformation_config\u001b[0;34m(self)\u001b[0m\n\u001b[1;32m     18\u001b[0m config \u001b[38;5;241m=\u001b[39m \u001b[38;5;28mself\u001b[39m\u001b[38;5;241m.\u001b[39mconfig\u001b[38;5;241m.\u001b[39mdata_validation\n\u001b[1;32m     20\u001b[0m create_directories([config\u001b[38;5;241m.\u001b[39mroot_dir])\n\u001b[1;32m     22\u001b[0m data_transformation_config \u001b[38;5;241m=\u001b[39m DataTransformationConfig(\n\u001b[1;32m     23\u001b[0m     root_dir\u001b[38;5;241m=\u001b[39mconfig\u001b[38;5;241m.\u001b[39mroot_dir,\n\u001b[0;32m---> 24\u001b[0m     data_path\u001b[38;5;241m=\u001b[39m\u001b[43mconfig\u001b[49m\u001b[38;5;241;43m.\u001b[39;49m\u001b[43mdata_path\u001b[49m,\n\u001b[1;32m     25\u001b[0m )\n\u001b[1;32m     27\u001b[0m \u001b[38;5;28;01mreturn\u001b[39;00m data_transformation_config\n",
      "File \u001b[0;32m/opt/anaconda3/envs/mlproj/lib/python3.8/site-packages/box/config_box.py:30\u001b[0m, in \u001b[0;36mbox.config_box.ConfigBox.__getattr__\u001b[0;34m()\u001b[0m\n",
      "File \u001b[0;32m/opt/anaconda3/envs/mlproj/lib/python3.8/site-packages/box/box.py:552\u001b[0m, in \u001b[0;36mbox.box.Box.__getattr__\u001b[0;34m()\u001b[0m\n",
      "\u001b[0;31mBoxKeyError\u001b[0m: \"'ConfigBox' object has no attribute 'data_path'\""
     ]
    }
   ],
   "source": [
    "try:\n",
    "    config = ConfigurationManager()\n",
    "    data_transformation_config = config.get_data_transformation_config()\n",
    "    data_transformation = DataTransformation(config=data_transformation_config)\n",
    "    data_transformation.train_test_splitting()\n",
    "except Exception as e:\n",
    "    raise e\n"
   ]
  }
 ],
 "metadata": {
  "kernelspec": {
   "display_name": "mlproj",
   "language": "python",
   "name": "python3"
  },
  "language_info": {
   "codemirror_mode": {
    "name": "ipython",
    "version": 3
   },
   "file_extension": ".py",
   "mimetype": "text/x-python",
   "name": "python",
   "nbconvert_exporter": "python",
   "pygments_lexer": "ipython3",
   "version": "3.8.20"
  }
 },
 "nbformat": 4,
 "nbformat_minor": 2
}
